<?xml version="1.0" ?>
<robot name="simple_three_dof_robotic_arm">
    <link name="dummy_link" />
    <!-- Base Link -->
    <link name="base_link">
        <visual>
            <geometry>
                <cylinder length="0.2" radius="0.2" />
            </geometry>
            <origin xyz="0 0 0.1" rpy="0 0 0" />
            <material name="link_color">
                <color rgba="0.5 0.5 0.5 1.0" />
            </material>
        </visual>
        <collision>
            <geometry>
                <cylinder length="0.2" radius="0.2" />
            </geometry>
        </collision>
        <inertial>
            <mass value="0.1" />
            <origin xyz="0 0 0" rpy="0 0 0" />
            <inertia ixx="0.03" iyy="0.03" izz="0.03" ixy="0.0" ixz="0.0" iyz="0.0" />
        </inertial>
    </link>
    
    <!-- Fixed Joint Connecting Dummy Link to Base Link -->
    <joint name="dummy_joint" type="fixed">
        <parent link="dummy_link" />
        <child link="base_link" />
        <origin xyz="0 0 0" rpy="0 0 0" />
    </joint>
    <!-- Link 1 -->
    <link name="link1">
        <visual>
            <origin xyz="0 0 0.15" rpy="0 0 0" />
            <geometry>
                <box size="0.1 0.1 0.3" />
            </geometry>
            <material name="link1b_color">
                <color rgba="0.6 0.6 0.6 1.0" />
            </material>
        </visual>
        <visual>
            <origin xyz="0 0 0.3" rpy="0 0 0" />
            <geometry>
                <sphere radius="0.05" />
            </geometry>
            <material name="link1s_color">
                <color rgba="0.6 0.6 0.6 1.0" />
            </material>
        </visual>
        <collision>
            <geometry>
                <box size="0.1 0.1 0.3" />
            </geometry>
        </collision>
        <inertial>
            <mass value="3.0" />
            <inertia ixx="0.01" ixy="0" ixz="0" iyy="0.01" iyz="0" izz="0.01" />
            <origin xyz="0 0 0" rpy="0 0 0" />
        </inertial>
    </link>
    <!-- Joint 1 (Base to Link1) -->
    <joint name="joint1" type="revolute">
        <parent link="base_link" />
        <child link="link1" />
        <origin xyz="0 0 0.1" rpy="0 0 0" />
        <axis xyz="0 0 1" />
        <limit lower="-1.5708" upper="2.09" effort="10" velocity="1.0" />
    </joint>
    <!-- Link 2 -->
    <link name="link2">
        <visual>
            <origin xyz="0 0 0.15" rpy="0 0 0" />
            <geometry>
                <box size="0.1 0.1 0.3" />
            </geometry>
            <material name="link2b_color">
                <color rgba="0.7 0.7 0.7 1.0" />
            </material>
        </visual>
        <visual>
            <origin xyz="0 0 0.3" rpy="0 0 0" />
            <geometry>
                <sphere radius="0.05" />
            </geometry>
            <material name="link2s_color">
                <color rgba="0.7 0.7 0.7 1.0" />
            </material>
        </visual>
        <collision>
            <geometry>
                <box size="0.1 0.1 0.3" />
            </geometry>
        </collision>
        <inertial>
            <mass value="2.0" />
            <inertia ixx="0.008" ixy="0" ixz="0" iyy="0.008" iyz="0" izz="0.008" />
            <origin xyz="0 0 0" rpy="0 0 0" />
        </inertial>
    </link>
    <!-- Joint 2 (Link1 to Link2) -->
    <joint name="joint2" type="revolute">
        <parent link="link1" />
        <child link="link2" />
        <origin xyz="0 0 0.3" rpy="0 0 0" />
        <axis xyz="0 1 0" />
        <limit lower="-1.5708" upper="2.09" effort="10" velocity="1.0" />
    </joint>
    <!-- Link 3 -->
    <link name="link3">
        <visual>
            <origin xyz="0 0 0.15" rpy="0 0 0" />
            <geometry>
                <box size="0.1 0.1 0.3" />
            </geometry>
            <material name="link3s_color">
                <color rgba="0.8 0.8 0.8 1.0" />
            </material>
        </visual>
        <collision>
            <geometry>
                <box size="0.1 0.1 0.3" />
            </geometry>
        </collision>
        <inertial>
            <mass value="1.0" />
            <inertia ixx="0.005" ixy="0" ixz="0" iyy="0.005" iyz="0" izz="0.005" />
            <origin xyz="0 0 0" rpy="0 0 0" />
        </inertial>
    </link>
    <!-- Joint 3 (Link2 to Link3) -->
    <joint name="joint3" type="revolute">
        <parent link="link2" />
        <child link="link3" />
        <origin xyz="0 0 0.3" rpy="0 0 0" />
        <axis xyz="0 1 0" />
        <limit lower="-1.5708" upper="1.5708" effort="10" velocity="1.0" />
    </joint>
    <link name="extendable_part">
        <visual>
            <geometry>
                <cylinder length="0.5" radius="0.01" />
            </geometry>
            <material name="link_ex_color">
                <color rgba="1.0 1.0 1.0 1.0" />
            </material>
            <origin xyz="0 0 0.1" rpy="0 0 0" />
        </visual>
        <collision>
            <geometry>
                <cylinder length="0.2" radius="0.05" />
            </geometry>
            <origin xyz="0 0 0.1" rpy="0 0 0" />
        </collision>
        <inertial>
            <mass value="0.5" />
            <inertia ixx="0.001" ixy="0" ixz="0" iyy="0.001" iyz="0" izz="0.001" />
            <origin xyz="0 0 0" rpy="0 0 0" />
        </inertial>
    </link>
    <!-- Prismatic Joint (Link3 to Extendable Part) -->
    <joint name="prismatic_joint" type="prismatic">
        <parent link="link3" />
        <child link="extendable_part" />
        <origin xyz="0 0 0.1" rpy="0 0 0" />
        <axis xyz="0 0 1" />
        <limit lower="0" upper="0.3" effort="5" velocity="6.0" />
    </joint>
    <link name="button1">
        <visual>
            <origin xyz="0 0 0" rpy="0 0 0" />
            <geometry>
                <box size="0.1 0.1 0.1" />
            </geometry>
            <material name="red">
                <color rgba="1 0 0 1" />
            </material>
        </visual>
        <collision>
            <geometry>
                <box size="0.1 0.1 0.1" />
            </geometry>
        </collision>
        <inertial>
            <mass value="0.1" />
            <origin xyz="0 0 0" rpy="0 0 0" />
            <inertia ixx="0.03" iyy="0.03" izz="0.03" ixy="0.0" ixz="0.0" iyz="0.0" />
        </inertial>
    </link>
    <joint name="button1_joint" type="fixed">
        <parent link="base_link" />
        <!-- Connect to an existing link in your robot -->
        <child link="button1" />
        <origin xyz="0.9 0 0.1" rpy="0 0 0" />
        <!-- Position of button1 relative to the parent link -->
    </joint>
    <link name="button2">
        <visual>
            <origin xyz="0 0 0" rpy="0 0 0" />
            <geometry>
                <box size="0.1 0.1 0.1" />
            </geometry>
            <material name="red">
                <color rgba="1 0 0 1" />
            </material>
        </visual>
        <collision>
            <geometry>
                <box size="0.1 0.1 0.1" />
            </geometry>
        </collision>
        <inertial>
            <mass value="0.1" />
            <origin xyz="0 0 0" rpy="0 0 0" />
            <inertia ixx="0.03" iyy="0.03" izz="0.03" ixy="0.0" ixz="0.0" iyz="0.0" />
        </inertial>
    </link>
    <joint name="button2_joint" type="fixed">
        <parent link="base_link" />
        <!-- Connect to an existing link in your robot -->
        <child link="button2" />
        <origin xyz="0.9 0 0.3" rpy="0 0 0" />
        <!-- Position of button1 relative to the parent link -->
    </joint>
    <link name="button3">
        <visual>
            <origin xyz="0 0 0" rpy="0 0 0" />
            <geometry>
                <box size="0.1 0.1 0.1" />
            </geometry>
            <material name="red">
                <color rgba="1 0 0 1" />
            </material>
        </visual>
        <collision>
            <geometry>
                <box size="0.1 0.1 0.1" />
            </geometry>
        </collision>
        <inertial>
            <mass value="0.1" />
            <origin xyz="0 0 0" rpy="0 0 0" />
            <inertia ixx="0.03" iyy="0.03" izz="0.03" ixy="0.0" ixz="0.0" iyz="0.0" />
        </inertial>
    </link>
    <joint name="button3_joint" type="fixed">
        <parent link="base_link" />
        <!-- Connect to an existing link in your robot -->
        <child link="button3" />
        <origin xyz="0.9 0 0.5" rpy="0 0 0" />
        <!-- Position of button1 relative to the parent link -->
    </joint>
    <link name="button4">
        <visual>
            <origin xyz="0 0 0" rpy="0 0 0" />
            <geometry>
                <box size="0.1 0.1 0.1" />
            </geometry>
            <material name="red">
                <color rgba="1 0 0 1" />
            </material>
        </visual>
        <collision>
            <geometry>
                <box size="0.1 0.1 0.1" />
            </geometry>
        </collision>
        <inertial>
            <mass value="0.1" />
            <origin xyz="0 0 0" rpy="0 0 0" />
            <inertia ixx="0.03" iyy="0.03" izz="0.03" ixy="0.0" ixz="0.0" iyz="0.0" />
        </inertial>
    </link>
    <joint name="button4_joint" type="fixed">
        <parent link="base_link" />
        <!-- Connect to an existing link in your robot -->
        <child link="button4" />
        <origin xyz="0.9 0 0.7" rpy="0 0 0" />
        <!-- Position of button1 relative to the parent link -->
    </joint>
    <link name="button5">
        <visual>
            <origin xyz="0 0 0" rpy="0 0 0" />
            <geometry>
                <box size="0.1 0.1 0.1" />
            </geometry>
            <material name="red">
                <color rgba="1 0 0 1" />
            </material>
        </visual>
        <collision>
            <geometry>
                <box size="0.1 0.1 0.1" />
            </geometry>
        </collision>
        <inertial>
            <mass value="0.1" />
            <origin xyz="0 0 0" rpy="0 0 0" />
            <inertia ixx="0.03" iyy="0.03" izz="0.03" ixy="0.0" ixz="0.0" iyz="0.0" />
        </inertial>
    </link>
    <joint name="button5_joint" type="fixed">
        <parent link="base_link" />
        <!-- Connect to an existing link in your robot -->
        <child link="button5" />
        <origin xyz="0.9 0 0.9" rpy="0 0 0" />
        <!-- Position of button1 relative to the parent link -->
    </joint>
    <transmission name="trans_joint1">
        <type>transmission_interface/SimpleTransmission</type>
        <joint name="joint1">
            <hardwareInterface>hardware_interface/PositionJointInterface</hardwareInterface>
        </joint>
        <actuator name="joint1_motor">
            <hardwareInterface>hardware_interface/PositionJointInterface</hardwareInterface>
            <mechanicalReduction>1</mechanicalReduction>
        </actuator>
    </transmission>
    <transmission name="trans_joint2">
        <type>transmission_interface/SimpleTransmission</type>
        <joint name="joint2">
            <hardwareInterface>hardware_interface/PositionJointInterface</hardwareInterface>
        </joint>
        <actuator name="joint2_motor">
            <hardwareInterface>hardware_interface/PositionJointInterface</hardwareInterface>
            <mechanicalReduction>1</mechanicalReduction>
        </actuator>
    </transmission>
    <transmission name="trans_joint3">
        <type>transmission_interface/SimpleTransmission</type>
        <joint name="joint3">
            <hardwareInterface>hardware_interface/PositionJointInterface</hardwareInterface>
        </joint>
        <actuator name="joint3_motor">
            <hardwareInterface>hardware_interface/PositionJointInterface</hardwareInterface>
            <mechanicalReduction>1</mechanicalReduction>
        </actuator>
    </transmission>
    <transmission name="trans_prismatic_joint">
        <type>transmission_interface/SimpleTransmission</type>
        <joint name="prismatic_joint">
            <hardwareInterface>hardware_interface/PositionJointInterface</hardwareInterface>
        </joint>
        <actuator name="prismatic_joint_motor">
            <hardwareInterface>hardware_interface/PositionJointInterface</hardwareInterface>
            <mechanicalReduction>1</mechanicalReduction>
        </actuator>
    </transmission>
    <gazebo>
        <plugin name="gazebo_ros_control" filename="libgazebo_ros_control.so">
            <robotNamespace>/</robotNamespace>
        </plugin>
    </gazebo>
    <gazebo reference="link3">
      <material>Gazebo/Blue</material>
    </gazebo>
</robot>

